Workbook
Name DaysPerYearRatio: 'Project Site Calendar'!$U$38
Name HoursPerDayRatio: 'Project Site Calendar'!$AF$15

Sheet BOM csv data
A1: http://www.bom.gov.au/climate/data/index.shtml?bookmark=200 | B1: 1. CLICK THE LINK TO THE LEFT TO ACCESS THE BoM Website; 2. Select the Location and pick the nearest BoM Station;
B2: 3. Get Data (Opens in new window); 4. Download data (csv) file of statistics; 5. Open the csv file in eXcel;
B3: 6. Highlight all data (A1:end) and Copy (Ctrl C); 7. PasteSpecialValues into Cell A5 below. See notes in CLIMATE TAB re Wind data
A4: DOWNLOAD BOM csv file & COPY+PASTE (all data) INTO CELL A5 using 'right click' :PasteSpecialValues to maintain formatting below. This data populates the Yellow 'Climate' Tab
A5: Monthly Climate Statistics for 'MOORABBIN AIRPORT' [086077]
A6: Created on [ 04 Apr 2018 14:44:16 GMT+00:00]
A8: 086077 MOORABBIN AIRPORT
A9: Commenced: 1950
A10: Last Record: 2018
A11: Latitude: 37.98 Degrees South
A12: Longitude: 145.10 Degrees East
A13: Elevation: 12 m
A14: State: VIC
A16: Statistic Element | B16: January | C16: February | D16: March | E16: April | F16: May | G16: June | H16: July | I16: August | J16: September | K16: October | L16: November | M16: December | N16: Annual | O16: Number of Years | P16: Start Year | Q16: End Year
A17: Mean maximum temperature (Degrees C) for years 1971 to 2018 | B17: 25.8 | C17: 26.1 | D17: 23.8 | E17: 20.2 | F17: 17 | G17: 14.2 | H17: 13.7 | I17: 14.9 | J17: 16.9 | K17: 19.3 | L17: 21.7 | M17: 24 | N17: 19.8 | O17: 46 | P17: 1971 | Q17: 2018
A18: Highest temperature (Degrees C) for years 1971 to 2018 | B18: 44.9 | C18: 46.7 | D18: 40.8 | E18: 34.9 | F18: 26.6 | G18: 23.7 | H18: 23.1 | I18: 25.6 | J18: 31.8 | K18: 36.2 | L18: 39.5 | M18: 43 | N18: 46.7 | O18: 46 | P18: 1971 | Q18: 2018
A19: Date of Highest temperature for years 1971 to 2018 | B19: 39842 | C19: 39851 | D19: 42437 | E19: 38452 | F19: 26421 | G19: 38511 | H19: 41473 | I19: 30192 | J19: 32046 | K19: 39002 | L19: 41242 | M19: 38717 | N19: 39851 | O19: N/A | P19: 1971 | Q19: 2018
A20: Lowest maximum temperature (Degrees C) for years 1971 to 2018 | B20: 15 | C20: 14.5 | D20: 14.5 | E20: 12.2 | F20: 8.4 | G20: 8.2 | H20: 6.6 | I20: 8.8 | J20: 9.4 | K20: 11.4 | L20: 12.5 | M20: 14.2 | N20: 6.6 | O20: 46 | P20: 1971 | Q20: 2018
A21: Date of Lowest maximum temperature for years 1971 to 2018 | B21: 35066 | C21: 32905 | D21: 28580 | E21: 34796 | F21: 28276 | G21: 27564 | H21: 26852 | I21: 38574 | J21: 34947 | K21: 36076 | L21: 34277 | M21: 34329 | N21: 26852 | O21: N/A | P21: 1971 | Q21: 2018
A22: Decile 1 maximum temperature (Degrees C) for years 1971 to 2018 | B22: 19.6 | C22: 19.9 | D22: 18.4 | E22: 15.9 | F22: 13.9 | G22: 11.8 | H22: 11.2 | I22: 12 | J22: 13.3 | K22: 14.6 | L22: 16.2 | M22: 18 | O22: 47 | P22: 1971 | Q22: 2018
A23: Decile 9 maximum temperature (Degrees C) for years 1971 to 2018 | B23: 35.3 | C23: 34.3 | D23: 31.5 | E23: 25.8 | F23: 21.2 | G23: 16.9 | H23: 16.3 | I23: 18.5 | J23: 22 | K23: 26 | L23: 29.8 | M23: 32.6 | O23: 47 | P23: 1971 | Q23: 2018
A24: Mean number of days >= 30 Degrees C for years 1971 to 2018 | B24: 7 | C24: 7.1 | D24: 4.3 | E24: 0.3 | F24: 0 | G24: 0 | H24: 0 | I24: 0 | J24: 0 | K24: 0.8 | L24: 2.9 | M24: 5.1 | N24: 27.5 | O24: 46 | P24: 1971 | Q24: 2018
A25: Mean number of days >= 35 Degrees C for years 1971 to 2018 | B25: 3.3 | C25: 2.1 | D25: 0.8 | E25: 0 | F25: 0 | G25: 0 | H25: 0 | I25: 0 | J25: 0 | K25: 0 | L25: 0.6 | M25: 1.9 | N25: 8.7 | O25: 46 | P25: 1971 | Q25: 2018
A26: Mean number of days >= 40 Degrees C for years 1971 to 2018 | B26: 0.7 | C26: 0.2 | D26: 0.1 | E26: 0 | F26: 0 | G26: 0 | H26: 0 | I26: 0 | J26: 0 | K26: 0 | L26: 0 | M26: 0.2 | N26: 1.2 | O26: 46 | P26: 1971 | Q26: 2018
A27: Mean minimum temperature (Degrees C) for years 1971 to 2018 | B27: 14.3 | C27: 14.4 | D27: 13 | E27: 10.5 | F27: 8.7 | G27: 6.7 | H27: 6.2 | I27: 6.9 | J27: 8.1 | K27: 9.3 | L27: 11.1 | M27: 12.7 | N27: 10.2 | O27: 46 | P27: 1971 | Q27: 2018
A28: Lowest temperature (Degrees C) for years 1971 to 2018 | B28: 6 | C28: 5.2 | D28: 2.9 | E28: 1 | F28: 0 | G28: -2.2 | H28: -3.8 | I28: -2.8 | J28: -1.8 | K28: 0.6 | L28: 2.2 | M28: 1.3 | N28: -3.8 | O28: 46 | P28: 1971 | Q28: 2018
A29: Date of Lowest temperature for years 1971 to 2018 | B29: 39816 | C29: 30009 | D29: 34041 | E29: 36279 | F29: 39592 | G29: 26474 | H29: 35641 | I29: 35646 | J29: 35702 | K29: 34271 | L29: 29529 | M29: 33940 | N29: 35641 | O29: N/A | P29: 1971 | Q29: 2018
A30: Highest minimum temperature (Degrees C) for years 1971 to 2018 | B30: 28.7 | C30: 25.3 | D30: 24 | E30: 22.6 | F30: 18.4 | G30: 15.7 | H30: 14.6 | I30: 16.8 | J30: 20.1 | K30: 23.1 | L30: 24.2 | M30: 28.5 | N30: 28.7 | O30: 46 | P30: 1971 | Q30: 2018
A31: Date of Highest minimum temperature for years 1971 to 2018 | B31: 42743 | C31: 29626 | D31: 39525 | E31: 41731 | F31: 32998 | G31: 37414 | H31: 34153 | I31: 38225 | J31: 36432 | K31: 43027 | L31: 31013 | M31: 42358 | N31: 42743 | O31: N/A | P31: 1971 | Q31: 2018
A32: Decile 1 minimum temperature (Degrees C) for years 1971 to 2018 | B32: 10.2 | C32: 10.3 | D32: 8.8 | E32: 6 | F32: 4.3 | G32: 2.3 | H32: 1.9 | I32: 3 | J32: 3.9 | K32: 5.1 | L32: 7.1 | M32: 9 | O32: 47 | P32: 1971 | Q32: 2018
A33: Decile 9 minimum temperature (Degrees C) for years 1971 to 2018 | B33: 18.5 | C33: 18.5 | D33: 17.3 | E33: 14.6 | F33: 12.7 | G33: 10.6 | H33: 9.7 | I33: 10.2 | J33: 11.7 | K33: 13.4 | L33: 15.2 | M33: 16.6 | O33: 47 | P33: 1971 | Q33: 2018
A34: Mean number of days <= 2 Degrees C for years 1971 to 2018 | B34: 0 | C34: 0 | D34: 0 | E34: 0.2 | F34: 0.7 | G34: 2.6 | H34: 3.3 | I34: 1.7 | J34: 0.7 | K34: 0.1 | L34: 0 | M34: 0 | N34: 9.3 | O34: 46 | P34: 1971 | Q34: 2018
A35: Mean number of days <= 0 Degrees C for years 1971 to 2018 | B35: 0 | C35: 0 | D35: 0 | E35: 0 | F35: 0 | G35: 0.6 | H35: 1.1 | I35: 0.3 | J35: 0.1 | K35: 0 | L35: 0 | M35: 0 | N35: 2.1 | O35: 46 | P35: 1971 | Q35: 2018
A36: Mean daily ground minimum temperature Degrees C for years null to null
A37: Lowest ground temperature Degrees C for years null to null
A38: Date of Lowest ground temperature for years null to null | O38: N/A
A39: Mean number of days ground min. temp. <= -1 Degrees C for years null to null
A40: Mean rainfall (mm) for years 1950 to 2018 | B40: 44.4 | C40: 45 | D40: 43.7 | E40: 62.5 | F40: 68.9 | G40: 55.9 | H40: 61.7 | I40: 65.1 | J40: 64.6 | K40: 68.8 | L40: 62.4 | M40: 60.5 | N40: 707.8 | O40: 61 | P40: 1950 | Q40: 2018
A41: Highest rainfall (mm) for years 1950 to 2018 | B41: 137 | C41: 215.2 | D41: 129.6 | E41: 158.8 | F41: 160.1 | G41: 139.8 | H41: 165 | I41: 127.7 | J41: 122.2 | K41: 165.4 | L41: 180.6 | M41: 146.6 | N41: 965.9 | O41: 65 | P41: 1950 | Q41: 2018
A42: Date of Highest rainfall for years 1950 to 2018 | B42: 1991 | C42: 2011 | D42: 1970 | E42: 2001 | F42: 1962 | G42: 1991 | H42: 1952 | I42: 1975 | J42: 1959 | K42: 1975 | L42: 1983 | M42: 1954 | N42: 1970 | O42: N/A | P42: 1950 | Q42: 2018
...

Sheet Climate
A1: ='BOM csv data'!A5 -> Monthly Climate Statistics for 'MOORABBIN AIRPORT' [086077]
A2: Statistics | B2: Jan | C2: Feb | D2: Mar | E2: Apr | F2: May | G2: Jun | H2: Jul | I2: Aug | J2: Sep | K2: Oct | L2: Nov | M2: Dec | N2: Annual | P2: NOTES (scroll down)
A3: Maximum temperature | P3: Click here to view Heat graph
A4: Mean maximum temperature (°C) | B4: ='BOM csv data'!B17 -> 25.8 | C4: ='BOM csv data'!C17 -> 26.1 | D4: ='BOM csv data'!D17 -> 23.8 | E4: ='BOM csv data'!E17 -> 20.2 | F4: ='BOM csv data'!F17 -> 17 | G4: ='BOM csv data'!G17 -> 14.2 | H4: ='BOM csv data'!H17 -> 13.7 | I4: ='BOM csv data'!I17 -> 14.9 | ... N4: ='BOM csv data'!N17 -> 19.8
A5: Highest temperature (°C) | B5: ='BOM csv data'!B18 -> 44.9 | C5: ='BOM csv data'!C18 -> 46.7 | D5: ='BOM csv data'!D18 -> 40.8 | E5: ='BOM csv data'!E18 -> 34.9 | F5: ='BOM csv data'!F18 -> 26.6 | G5: ='BOM csv data'!G18 -> 23.7 | H5: ='BOM csv data'!H18 -> 23.1 | I5: ='BOM csv data'!I18 -> 25.6 | ... N5: ='BOM csv data'!N18 -> 46.7
A6: Lowest maximum temperature (°C) | B6: ='BOM csv data'!B20 -> 15 | C6: ='BOM csv data'!C20 -> 14.5 | D6: ='BOM csv data'!D20 -> 14.5 | E6: ='BOM csv data'!E20 -> 12.2 | F6: ='BOM csv data'!F20 -> 8.4 | G6: ='BOM csv data'!G20 -> 8.2 | H6: ='BOM csv data'!H20 -> 6.6 | I6: ='BOM csv data'!I20 -> 8.8 | ... N6: ='BOM csv data'!N20 -> 6.6
A7: Decile 1 maximum temperature (°C) | B7: ='BOM csv data'!B22 -> 19.6 | C7: ='BOM csv data'!C22 -> 19.9 | D7: ='BOM csv data'!D22 -> 18.4 | E7: ='BOM csv data'!E22 -> 15.9 | F7: ='BOM csv data'!F22 -> 13.9 | G7: ='BOM csv data'!G22 -> 11.8 | H7: ='BOM csv data'!H22 -> 11.2 | I7: ='BOM csv data'!I22 -> 12 | ... N7: ='BOM csv data'!N22
A8: Decile 9 maximum temperature(°C) | B8: ='BOM csv data'!B23 -> 35.3 | C8: ='BOM csv data'!C23 -> 34.3 | D8: ='BOM csv data'!D23 -> 31.5 | E8: ='BOM csv data'!E23 -> 25.8 | F8: ='BOM csv data'!F23 -> 21.2 | G8: ='BOM csv data'!G23 -> 16.9 | H8: ='BOM csv data'!H23 -> 16.3 | I8: ='BOM csv data'!I23 -> 18.5 | ... N8: ='BOM csv data'!N23
A9: Mean number of days ≥ 30 °C | B9: ='BOM csv data'!B24 -> 7 | C9: ='BOM csv data'!C24 -> 7.1 | D9: ='BOM csv data'!D24 -> 4.3 | E9: ='BOM csv data'!E24 -> 0.3 | F9: ='BOM csv data'!F24 -> 0 | G9: ='BOM csv data'!G24 -> 0 | H9: ='BOM csv data'!H24 -> 0 | I9: ='BOM csv data'!I24 -> 0 | ... N9: ='BOM csv data'!N24 -> 27.5
A10: Mean number of days ≥ 32 °C | B10: =+B11+2.5*(B9-B11)/5 -> 5.15 | C10: =+C11+2.5*(C9-C11)/5 -> 4.6 | D10: =+D11+2.5*(D9-D11)/5 -> 2.55 | E10: =+E11+2.5*(E9-E11)/5 -> 0.15 | F10: =+F11+2.5*(F9-F11)/5 -> 0 | G10: =+G11+2.5*(G9-G11)/5 -> 0 | H10: =+H11+2.5*(H9-H11)/5 -> 0 | I10: =+I11+2.5*(I9-I11)/5 -> 0 | ... M10: =+M11+2.5*(M9-M11)/5 -> 3.5 | N10: =SUM(B10:M10) -> 18.1 | O10: <---Interpolated
A11: Mean number of days ≥ 35 °C | B11: ='BOM csv data'!B25 -> 3.3 | C11: ='BOM csv data'!C25 -> 2.1 | D11: ='BOM csv data'!D25 -> 0.8 | E11: ='BOM csv data'!E25 -> 0 | F11: ='BOM csv data'!F25 -> 0 | G11: ='BOM csv data'!G25 -> 0 | H11: ='BOM csv data'!H25 -> 0 | I11: ='BOM csv data'!I25 -> 0 | ... N11: ='BOM csv data'!N25 -> 8.7
A12: Mean number of days ≥ 37 °C | B12: =+B13+2.5*(B11-B13)/5 -> 2 | C12: =+C13+2.5*(C11-C13)/5 -> 1.15 | D12: =+D13+2.5*(D11-D13)/5 -> 0.45 | E12: =+E13+2.5*(E11-E13)/5 -> 0 | F12: =+F13+2.5*(F11-F13)/5 -> 0 | G12: =+G13+2.5*(G11-G13)/5 -> 0 | H12: =+H13+2.5*(H11-H13)/5 -> 0 | I12: =+I13+2.5*(I11-I13)/5 -> 0 | ... M12: =+M13+2.5*(M11-M13)/5 -> 1.05 | N12: =SUM(B12:M12) -> 4.95 | O12: <---Interpolated
A13: Mean number of days ≥ 40 °C | B13: ='BOM csv data'!B26 -> 0.7 | C13: ='BOM csv data'!C26 -> 0.2 | D13: ='BOM csv data'!D26 -> 0.1 | E13: ='BOM csv data'!E26 -> 0 | F13: ='BOM csv data'!F26 -> 0 | G13: ='BOM csv data'!G26 -> 0 | H13: ='BOM csv data'!H26 -> 0 | I13: ='BOM csv data'!I26 -> 0 | ... N13: ='BOM csv data'!N26 -> 1.2
A14: Minimum temperature | P14: Click here to view Cold Graph
A15: Mean minimum temperature (°C) | B15: ='BOM csv data'!B27 -> 14.3 | C15: ='BOM csv data'!C27 -> 14.4 | D15: ='BOM csv data'!D27 -> 13 | E15: ='BOM csv data'!E27 -> 10.5 | F15: ='BOM csv data'!F27 -> 8.7 | G15: ='BOM csv data'!G27 -> 6.7 | H15: ='BOM csv data'!H27 -> 6.2 | I15: ='BOM csv data'!I27 -> 6.9 | ... N15: ='BOM csv data'!N27 -> 10.2
A16: Lowest temperature (°C) | B16: ='BOM csv data'!B28 -> 6 | C16: ='BOM csv data'!C28 -> 5.2 | D16: ='BOM csv data'!D28 -> 2.9 | E16: ='BOM csv data'!E28 -> 1 | F16: ='BOM csv data'!F28 -> 0 | G16: ='BOM csv data'!G28 -> -2.2 | H16: ='BOM csv data'!H28 -> -3.8 | I16: ='BOM csv data'!I28 -> -2.8 | ... N16: ='BOM csv data'!N28 -> -3.8
A17: Highest minimum temperature (°C) | B17: ='BOM csv data'!B30 -> 28.7 | C17: ='BOM csv data'!C30 -> 25.3 | D17: ='BOM csv data'!D30 -> 24 | E17: ='BOM csv data'!E30 -> 22.6 | F17: ='BOM csv data'!F30 -> 18.4 | G17: ='BOM csv data'!G30 -> 15.7 | H17: ='BOM csv data'!H30 -> 14.6 | I17: ='BOM csv data'!I30 -> 16.8 | ... N17: ='BOM csv data'!N30 -> 28.7
A18: Decile 1 minimum temperature (°C) | B18: ='BOM csv data'!B32 -> 10.2 | C18: ='BOM csv data'!C32 -> 10.3 | D18: ='BOM csv data'!D32 -> 8.8 | E18: ='BOM csv data'!E32 -> 6 | F18: ='BOM csv data'!F32 -> 4.3 | G18: ='BOM csv data'!G32 -> 2.3 | H18: ='BOM csv data'!H32 -> 1.9 | I18: ='BOM csv data'!I32 -> 3 | ... N18: ='BOM csv data'!N32
A19: Decile 9 minimum temperature (°C) | B19: ='BOM csv data'!B33 -> 18.5 | C19: ='BOM csv data'!C33 -> 18.5 | D19: ='BOM csv data'!D33 -> 17.3 | E19: ='BOM csv data'!E33 -> 14.6 | F19: ='BOM csv data'!F33 -> 12.7 | G19: ='BOM csv data'!G33 -> 10.6 | H19: ='BOM csv data'!H33 -> 9.7 | I19: ='BOM csv data'!I33 -> 10.2 | ... N19: ='BOM csv data'!N33
A20: Mean number of days ≤ 2 °C | B20: ='BOM csv data'!B34 -> 0 | C20: ='BOM csv data'!C34 -> 0 | D20: ='BOM csv data'!D34 -> 0 | E20: ='BOM csv data'!E34 -> 0.2 | F20: ='BOM csv data'!F34 -> 0.7 | G20: ='BOM csv data'!G34 -> 2.6 | H20: ='BOM csv data'!H34 -> 3.3 | I20: ='BOM csv data'!I34 -> 1.7 | ... N20: ='BOM csv data'!N34 -> 9.3
A21: Mean number of days ≤ 0 °C | B21: ='BOM csv data'!B35 -> 0 | C21: ='BOM csv data'!C35 -> 0 | D21: ='BOM csv data'!D35 -> 0 | E21: ='BOM csv data'!E35 -> 0 | F21: ='BOM csv data'!F35 -> 0 | G21: ='BOM csv data'!G35 -> 0.6 | H21: ='BOM csv data'!H35 -> 1.1 | I21: ='BOM csv data'!I35 -> 0.3 | ... N21: ='BOM csv data'!N35 -> 2.1
A22: Ground surface temperature
A23: Mean daily ground minimum temperature (°C) | B23: ='BOM csv data'!B36 | C23: ='BOM csv data'!C36 | D23: ='BOM csv data'!D36 | E23: ='BOM csv data'!E36 | F23: ='BOM csv data'!F36 | G23: ='BOM csv data'!G36 | H23: ='BOM csv data'!H36 | I23: ='BOM csv data'!I36 | ... N23: ='BOM csv data'!N36
A24: Lowest ground temperature (°C) | B24: ='BOM csv data'!B37 | C24: ='BOM csv data'!C37 | D24: ='BOM csv data'!D37 | E24: ='BOM csv data'!E37 | F24: ='BOM csv data'!F37 | G24: ='BOM csv data'!G37 | H24: ='BOM csv data'!H37 | I24: ='BOM csv data'!I37 | ... N24: ='BOM csv data'!N37
A25: Mean number of days ground min. temp. ≤ -1 °C | B25: ='BOM csv data'!B39 | C25: ='BOM csv data'!C39 | D25: ='BOM csv data'!D39 | E25: ='BOM csv data'!E39 | F25: ='BOM csv data'!F39 | G25: ='BOM csv data'!G39 | H25: ='BOM csv data'!H39 | I25: ='BOM csv data'!I39 | ... N25: ='BOM csv data'!N39
A26: Rainfall | P26: Click here to view Rainfall Graph
A27: Highest rainfall (mm) | B27: ='BOM csv data'!B41 -> 137 | C27: ='BOM csv data'!C41 -> 215.2 | D27: ='BOM csv data'!D41 -> 129.6 | E27: ='BOM csv data'!E41 -> 158.8 | F27: ='BOM csv data'!F41 -> 160.1 | G27: ='BOM csv data'!G41 -> 139.8 | H27: ='BOM csv data'!H41 -> 165 | I27: ='BOM csv data'!I41 -> 127.7 | ... N27: ='BOM csv data'!N41 -> 965.9
A28: Decile 9 rainfall (mm) | B28: ='BOM csv data'!B47 -> 91.7 | C28: ='BOM csv data'!C47 -> 89.5 | D28: ='BOM csv data'!D47 -> 74.4 | E28: ='BOM csv data'!E47 -> 107 | F28: ='BOM csv data'!F47 -> 108.6 | G28: ='BOM csv data'!G47 -> 85.1 | H28: ='BOM csv data'!H47 -> 94.9 | I28: ='BOM csv data'!I47 -> 95.4 | ... N28: ='BOM csv data'!N47 -> 884.9
A29: Mean rainfall (mm) | B29: ='BOM csv data'!B40 -> 44.4 | C29: ='BOM csv data'!C40 -> 45 | D29: ='BOM csv data'!D40 -> 43.7 | E29: ='BOM csv data'!E40 -> 62.5 | F29: ='BOM csv data'!F40 -> 68.9 | G29: ='BOM csv data'!G40 -> 55.9 | H29: ='BOM csv data'!H40 -> 61.7 | I29: ='BOM csv data'!I40 -> 65.1 | ... N29: ='BOM csv data'!N40 -> 707.8
A30: Decile 5 (median) rainfall (mm) | B30: ='BOM csv data'!B46 -> 38 | C30: ='BOM csv data'!C46 -> 33.6 | D30: ='BOM csv data'!D46 -> 39.8 | E30: ='BOM csv data'!E46 -> 62.5 | F30: ='BOM csv data'!F46 -> 65.4 | G30: ='BOM csv data'!G46 -> 55.8 | H30: ='BOM csv data'!H46 -> 60.6 | I30: ='BOM csv data'!I46 -> 64.8 | ... N30: ='BOM csv data'!N46 -> 708.9
A31: Decile 1 rainfall (mm) | B31: ='BOM csv data'!B45 -> 14.9 | C31: ='BOM csv data'!C45 -> 4.5 | D31: ='BOM csv data'!D45 -> 16.5 | E31: ='BOM csv data'!E45 -> 23.6 | F31: ='BOM csv data'!F45 -> 29.2 | G31: ='BOM csv data'!G45 -> 22.9 | H31: ='BOM csv data'!H45 -> 29.7 | I31: ='BOM csv data'!I45 -> 36.1 | ... N31: ='BOM csv data'!N45 -> 528.6
A32: Lowest rainfall (mm) | B32: ='BOM csv data'!B43 -> 1.2 | C32: ='BOM csv data'!C43 -> 0.3 | D32: ='BOM csv data'!D43 -> 5.4 | E32: ='BOM csv data'!E43 -> 8.2 | F32: ='BOM csv data'!F43 -> 15.2 | G32: ='BOM csv data'!G43 -> 5.6 | H32: ='BOM csv data'!H43 -> 12.4 | I32: ='BOM csv data'!I43 -> 12 | ... N32: ='BOM csv data'!N43 -> 443.8
A33: Highest daily rainfall (mm) | B33: ='BOM csv data'!B48 -> 91 | C33: ='BOM csv data'!C48 -> 140.8 | D33: ='BOM csv data'!D48 -> 45 | E33: ='BOM csv data'!E48 -> 64 | F33: ='BOM csv data'!F48 -> 53.2 | G33: ='BOM csv data'!G48 -> 51.3 | H33: ='BOM csv data'!H48 -> 61.5 | I33: ='BOM csv data'!I48 -> 42.8 | ... N33: ='BOM csv data'!N48 -> 140.8
A34: Mean number of days of rain | B34: ='BOM csv data'!B50 -> 7.9 | C34: ='BOM csv data'!C50 -> 6.9 | D34: ='BOM csv data'!D50 -> 9.1 | E34: ='BOM csv data'!E50 -> 11.6 | F34: ='BOM csv data'!F50 -> 14.8 | G34: ='BOM csv data'!G50 -> 14.8 | H34: ='BOM csv data'!H50 -> 17 | I34: ='BOM csv data'!I50 -> 17 | ... N34: ='BOM csv data'!N50 -> 149.9
A35: Mean number of rain days < 1 mm | B35: =+B34-B37-B39-B40 -> 2.5 | C35: =+C34-C37-C39-C40 -> 2.4 | D35: =+D34-D37-D39-D40 -> 3.3 | E35: =+E34-E37-E39-E40 -> 3.5 | F35: =+F34-F37-F39-F40 -> 4 | G35: =+G34-G37-G39-G40 -> 5 | H35: =+H34-H37-H39-H40 -> 5.6 | I35: =+I34-I37-I39-I40 -> 4.9 | ... M35: =+M34-M37-M39-M40 -> 2.9 | N35: =SUM(B35:M35) -> 45.9 | O35: <---Interpolated | P35: <-----Used in GREEN TAB <1mm
A36: Mean number of days of rain ≥ 1 mm | B36: ='BOM csv data'!B51 -> 5.4 | C36: ='BOM csv data'!C51 -> 4.5 | D36: ='BOM csv data'!D51 -> 5.8 | E36: ='BOM csv data'!E51 -> 8.1 | F36: ='BOM csv data'!F51 -> 10.8 | G36: ='BOM csv data'!G51 -> 9.8 | H36: ='BOM csv data'!H51 -> 11.4 | I36: ='BOM csv data'!I51 -> 12.1 | ... N36: ='BOM csv data'!N51 -> 104
A37: Mean number of rain days ≥ 1 mm and < 10 mm | B37: =+B36-B38 -> 4 | C37: =+C36-C38 -> 3.1 | D37: =+D36-D38 -> 4.4 | E37: =+E36-E38 -> 6.3 | F37: =+F36-F38 -> 8.8 | G37: =+G36-G38 -> 8.3 | H37: =+H36-H38 -> 10 | I37: =+I36-I38 -> 10.4 | ... N37: =+N36-N38 -> 83.4 | O37: <---Interpolated | P37: <-----Used in GREEN TAB ≥ 1 mm & < 10 mm
A38: Mean number of days of rain ≥ 10 mm | B38: ='BOM csv data'!B52 -> 1.4 | C38: ='BOM csv data'!C52 -> 1.4 | D38: ='BOM csv data'!D52 -> 1.4 | E38: ='BOM csv data'!E52 -> 1.8 | F38: ='BOM csv data'!F52 -> 2 | G38: ='BOM csv data'!G52 -> 1.5 | H38: ='BOM csv data'!H52 -> 1.4 | I38: ='BOM csv data'!I52 -> 1.7 | ... N38: ='BOM csv data'!N52 -> 20.6
A39: Mean number of rain days ≥ 10 mm and < 25 mm | B39: =+B38-B40 -> 1.1 | C39: =+C38-C40 -> 0.9 | D39: =+D38-D40 -> 1.2 | E39: =+E38-E40 -> 1.3 | F39: =+F38-F40 -> 1.8 | G39: =+G38-G40 -> 1.4 | H39: =+H38-H40 -> 1.2 | I39: =+I38-I40 -> 1.6 | ... N39: =+N38-N40 -> 17.2 | O39: <---Interpolated | P39: <-----Used in GREEN TAB ≥ 10 mm & < 25 mm
A40: Mean number of days of rain ≥ 25 mm | B40: ='BOM csv data'!B53 -> 0.3 | C40: ='BOM csv data'!C53 -> 0.5 | D40: ='BOM csv data'!D53 -> 0.2 | E40: ='BOM csv data'!E53 -> 0.5 | F40: ='BOM csv data'!F53 -> 0.2 | G40: ='BOM csv data'!G53 -> 0.1 | H40: ='BOM csv data'!H53 -> 0.2 | I40: ='BOM csv data'!I53 -> 0.1 | ... N40: ='BOM csv data'!N53 -> 3.4 | P40: <-----Used in GREEN TAB ≥ 25 mm
...

Sheet Weather Calculation
A1: Forecast Delay Allowances | F1: Annual Totals | H1: Year | N1: 2017
H2: 42736 | I2: 42767 | J2: 42798 | K2: 42829 | L2: 42860 | M2: 42891 | N2: 42922 | O2: 42953 | P2: 42984 | Q2: 43015 | R2: 43046 | S2: 43077
F3: Ratio:Work/MonthDays | H3: ='Project Site Calendar'!I38 -> 0.48387097 | I3: ='Project Site Calendar'!J38 -> 0.78571429 | J3: ='Project Site Calendar'!K38 -> 0.74193548 | K3: ='Project Site Calendar'!L38 -> 0.63333333 | L3: ='Project Site Calendar'!M38 -> 0.80645161 | M3: ='Project Site Calendar'!N38 -> 0.7 | N3: ='Project Site Calendar'!O38 -> 0.80645161 | O3: ='Project Site Calendar'!P38 -> 0.77419355 | ... S3: ='Project Site Calendar'!T38 -> 0.38709677
V4: INSTRUCTIONS :
A5: Hot Weather (Average days over 37 degrees celcius) Lose | E5: 0.4 | F5: =SUM(H5:S5) -> 1.1246544 | H5: =Climate!B12*$E$5*H$3 -> 0.38709677 | I5: =Climate!C12*$E$5*I$3 -> 0.36142857 | J5: =Climate!D12*$E$5*J$3 -> 0.13354839 | K5: =Climate!E12*$E$5*K$3 -> 0 | L5: =Climate!F12*$E$5*L$3 -> 0 | M5: =Climate!G12*$E$5*M$3 -> 0 | N5: =Climate!H12*$E$5*N$3 -> 0 | O5: =Climate!I12*$E$5*O$3 -> 0 | ... S5: =Climate!M12*$E$5*S$3 -> 0.16258065
A6: Cold Weather (<2 degress C.) Lose | E6: 0.2 | F6: =SUM(H6:S6) -> 1.421828 | H6: =Climate!B20*'Weather Calculation'!$E$6*H$3 -> 0 | I6: =Climate!C20*'Weather Calculation'!$E$6*I$3 -> 0 | J6: =Climate!D20*'Weather Calculation'!$E$6*J$3 -> 0 | K6: =Climate!E20*'Weather Calculation'!$E$6*K$3 -> 0.025333333 | L6: =Climate!F20*'Weather Calculation'!$E$6*L$3 -> 0.11290323 | M6: =Climate!G20*'Weather Calculation'!$E$6*M$3 -> 0.364 | N6: =Climate!H20*'Weather Calculation'!$E$6*N$3 -> 0.53225806 | O6: =Climate!I20*'Weather Calculation'!$E$6*O$3 -> 0.26322581 | ... S6: =Climate!M20*'Weather Calculation'!$E$6*S$3 -> 0 | V6: Populate the loss factors for Hot Day and Cold Day delays per month in cells E5 & E6. These rows use data from the Climate TAB to calc how many days per month we lose for extreme Hot or Cold days. These numbers are factored for how many days per month we will be working.
A7: Manual Input : Wind (Assumption) | F7: =SUM(H7:S7) -> 2 | H7: 0.5 | Q7: 0.5 | R7: 0.5 | S7: 0.5
A8: Manual Input : Client / Authority Delays | F8: =SUM(H8:S8) -> 0
A9: Manual Input : Subcontractor Delays | F9: =SUM(H9:S9) -> 0
A10: Manual Input : Industrial (Assumption) | F10: =SUM(H10:S10) -> 2 | K10: 0 | M10: 0.5 | O10: 0.5 | Q10: 0.5 | S10: 0.5
A11: Manual Input : Plant Delays | F11: =SUM(H11:S11) -> 0 | V11: In cells H7 to S12 manually populate Wind + other potential delays based on Climate stats and other data. The Climate TAB has a graph showing Mean 9am and 3pm wind speeds (for reference). Note - These numbers are NOT factored below to account for WorkHours/Day or WorkDays/Month - so numbers entered here will carry forward to the Red TAB unchanged
A12: Manual Input : Other Delays | F12: =SUM(H12:S12) -> 0
A13: Monthly Total (Working Days lost per Calendar Month) | F13: =SUM(H13:S13) -> 6.5464823 | H13: =SUM(H5:H12)+H4 -> 0.88709677 | I13: =SUM(I5:I12)+I4 -> 0.36142857 | J13: =SUM(J5:J12)+J4 -> 0.13354839 | K13: =SUM(K5:K12)+K4 -> 0.025333333 | L13: =SUM(L5:L12)+L4 -> 0.11290323 | M13: =SUM(M5:M12)+M4 -> 0.864 | N13: =SUM(N5:N12)+N4 -> 0.53225806 | O13: =SUM(O5:O12)+O4 -> 0.76322581 | ... S13: =SUM(S5:S12)+S4 -> 1.1625806
A14: Percentage Work Days Lost | F14: =+F13/'Project Site Calendar'!U37 -> 0.02567248 | H14: =+H13/'Project Site Calendar'!I37 -> 0.059139785 | I14: =+I13/'Project Site Calendar'!J37 -> 0.016428571 | J14: =+J13/'Project Site Calendar'!K37 -> 0.0058064516 | K14: =+K13/'Project Site Calendar'!L37 -> 0.0013333333 | L14: =+L13/'Project Site Calendar'!M37 -> 0.004516129 | M14: =+M13/'Project Site Calendar'!N37 -> 0.041142857 | N14: =+N13/'Project Site Calendar'!O37 -> 0.021290323 | O14: =+O13/'Project Site Calendar'!P37 -> 0.031801075 | ... S14: =+S13/'Project Site Calendar'!T37 -> 0.09688172
A15: Cumulative Total (Working Days Lost) | H15: =G15+H13 -> 0.88709677 | I15: =H15+I13 -> 1.2485253 | J15: =I15+J13 -> 1.3820737 | K15: =J15+K13 -> 1.4074071 | L15: =K15+L13 -> 1.5203103 | M15: =L15+M13 -> 2.3843103 | N15: =M15+N13 -> 2.9165684 | O15: =N15+O13 -> 3.6797942 | ... S15: =R15+S13 -> 6.5464823
A16: Calculation Notes
H19: 1 | I19: =+H19+1 -> 2 | J19: =+I19+1 -> 3 | K19: =+J19+1 -> 4 | L19: =+K19+1 -> 5 | M19: =+L19+1 -> 6 | N19: =+M19+1 -> 7 | O19: =+N19+1 -> 8 | P19: =+O19+1 -> 9 | ... S19: =+R19+1 -> 12
G20: Rain | H20: =Climate!B193 -> Low | I20: =Climate!C193 -> Low | J20: =Climate!D193 -> Low | K20: =Climate!E193 -> Med | L20: =Climate!F193 -> Med | M20: =Climate!G193 -> Med | N20: =Climate!H193 -> Med | O20: =Climate!I193 -> Med | ... S20: =Climate!M193 -> Med
G21: Heat | H21: =Climate!B154 -> High | I21: =Climate!C154 -> High | J21: =Climate!D154 -> Med | K21: =Climate!E154 -> Med | L21: =Climate!F154 -> Low | M21: =Climate!G154 -> Low | N21: =Climate!H154 -> Low | O21: =Climate!I154 -> Low | ... S21: =Climate!M154 -> Med
G22: Cold / Frost | H22: =Climate!B174 -> Low | I22: =Climate!C174 -> Low | J22: =Climate!D174 -> Med | K22: =Climate!E174 -> High | L22: =Climate!F174 -> High | M22: =Climate!G174 -> High | N22: =Climate!H174 -> High | O22: =Climate!I174 -> High | ... S22: =Climate!M174 -> High
G23: Wind | H23: =Climate!B210 -> Med | I23: =Climate!C210 -> Med | J23: =Climate!D210 -> Med | K23: =Climate!E210 -> Low | L23: =Climate!F210 -> Low | M23: =Climate!G210 -> Low | N23: =Climate!H210 -> Med | O23: =Climate!I210 -> Med | ... S23: =Climate!M210 -> Med
A25: Working Days | F25: Totals | V25: Row 27 auto populates from the Orange TAB and is used as a lookup table in the Red TAB. These rows show number of working days each month. Row 3 shows the %age ratio of WorkDays/DaysperMonth
H26: 1 | I26: =+H26+1 -> 2 | J26: =+I26+1 -> 3 | K26: =+J26+1 -> 4 | L26: =+K26+1 -> 5 | M26: =+L26+1 -> 6 | N26: =+M26+1 -> 7 | O26: =+N26+1 -> 8 | P26: =+O26+1 -> 9 | ... S26: =+R26+1 -> 12
A27: Gross Work Days Per Month (ie Cal Days - Hols, RDOs, NWDs etc) | F27: =SUM(H27:S27) -> 255 | H27: =+'Project Site Calendar'!I37 -> 15 | I27: =+'Project Site Calendar'!J37 -> 22 | J27: =+'Project Site Calendar'!K37 -> 23 | K27: =+'Project Site Calendar'!L37 -> 19 | L27: =+'Project Site Calendar'!M37 -> 25 | M27: =+'Project Site Calendar'!N37 -> 21 | N27: =+'Project Site Calendar'!O37 -> 25 | O27: =+'Project Site Calendar'!P37 -> 24 | ... S27: =+'Project Site Calendar'!T37 -> 12
A28: Cumulative Gross Work Days per Calendar Year | H28: =H27 -> 15 | I28: =H28+I27 -> 37 | J28: =I28+J27 -> 60 | K28: =J28+K27 -> 79 | L28: =K28+L27 -> 104 | M28: =L28+M27 -> 125 | N28: =M28+N27 -> 150 | O28: =N28+O27 -> 174 | P28: =O28+P27 -> 197 | ... S28: =R28+S27 -> 255
A32: Rainfall | B32: Direct | C32: Consequential | D32: Total
A33: <1mm | B33: ='Rain+Other Factors'!C8 -> 0 | C33: ='Rain+Other Factors'!D8 -> 0 | D33: =SUM(B33:C33) -> 0 | F33: =SUM(H33:S33) -> 0 | H33: =+Climate!B35*$D33*HoursPerDayRatio*H$3 -> 0 | I33: =+Climate!C35*$D33*HoursPerDayRatio*I$3 -> 0 | J33: =+Climate!D35*$D33*HoursPerDayRatio*J$3 -> 0 | K33: =+Climate!E35*$D33*HoursPerDayRatio*K$3 -> 0 | L33: =+Climate!F35*$D33*HoursPerDayRatio*L$3 -> 0 | M33: =+Climate!G35*$D33*HoursPerDayRatio*M$3 -> 0 | N33: =+Climate!H35*$D33*HoursPerDayRatio*N$3 -> 0 | O33: =+Climate!I35*$D33*HoursPerDayRatio*O$3 -> 0 | ... S33: =+Climate!M35*$D33*HoursPerDayRatio*S$3 -> 0
A34: ≥ 1 mm & < 10 mm | B34: ='Rain+Other Factors'!C9 -> 0.5 | C34: ='Rain+Other Factors'!D9 -> 1 | D34: =SUM(B34:C34) -> 1.5 | F34: =SUM(H34:S34) -> 33.797791 | H34: =+Climate!B37*$D34*HoursPerDayRatio*H$3 -> 1.0887097 | I34: =+Climate!C37*$D34*HoursPerDayRatio*I$3 -> 1.3700893 | J34: =+Climate!D37*$D34*HoursPerDayRatio*J$3 -> 1.8362903 | K34: =+Climate!E37*$D34*HoursPerDayRatio*K$3 -> 2.244375 | L34: =+Climate!F37*$D34*HoursPerDayRatio*L$3 -> 3.9919355 | M34: =+Climate!G37*$D34*HoursPerDayRatio*M$3 -> 3.268125 | N34: =+Climate!H37*$D34*HoursPerDayRatio*N$3 -> 4.5362903 | O34: =+Climate!I37*$D34*HoursPerDayRatio*O$3 -> 4.5290323 | ... S34: =+Climate!M37*$D34*HoursPerDayRatio*S$3 -> 1.1540323
A35: ≥ 10 mm & < 25 mm | B35: ='Rain+Other Factors'!C10 -> 1 | C35: ='Rain+Other Factors'!D10 -> 1 | D35: =SUM(B35:C35) -> 2 | F35: =SUM(H35:S35) -> 9.1095507 | H35: =+Climate!B39*$D35*HoursPerDayRatio*H$3 -> 0.39919355 | I35: =+Climate!C39*$D35*HoursPerDayRatio*I$3 -> 0.53035714 | J35: =+Climate!D39*$D35*HoursPerDayRatio*J$3 -> 0.66774194 | K35: =+Climate!E39*$D35*HoursPerDayRatio*K$3 -> 0.6175 | L35: =+Climate!F39*$D35*HoursPerDayRatio*L$3 -> 1.0887097 | M35: =+Climate!G39*$D35*HoursPerDayRatio*M$3 -> 0.735 | N35: =+Climate!H39*$D35*HoursPerDayRatio*N$3 -> 0.72580645 | O35: =+Climate!I39*$D35*HoursPerDayRatio*O$3 -> 0.92903226 | ... S35: =+Climate!M39*$D35*HoursPerDayRatio*S$3 -> 0.40645161
A36: ≥ 25 mm | B36: ='Rain+Other Factors'!C11 -> 1 | C36: ='Rain+Other Factors'!D11 -> 2 | D36: =SUM(B36:C36) -> 3 | F36: =SUM(H36:S36) -> 6.8147005 | H36: =+Climate!B40*$D36*H$3 -> 0.43548387 | I36: =+Climate!C40*$D36*I$3 -> 1.1785714 | J36: =+Climate!D40*$D36*J$3 -> 0.44516129 | K36: =+Climate!E40*$D36*K$3 -> 0.95 | L36: =+Climate!F40*$D36*L$3 -> 0.48387097 | M36: =+Climate!G40*$D36*M$3 -> 0.21 | N36: =+Climate!H40*$D36*N$3 -> 0.48387097 | O36: =+Climate!I40*$D36*O$3 -> 0.23225806 | ... S36: =+Climate!M40*$D36*S$3 -> 0.58064516
A37: RAIN EXPOSURE 1 : Bulk + Inground Works | F37: =SUM(H37:S37) -> 49.722042 | H37: =SUM(H33:H36) -> 1.9233871 | I37: =SUM(I33:I36) -> 3.0790179 | J37: =SUM(J33:J36) -> 2.9491935 | K37: =SUM(K33:K36) -> 3.811875 | L37: =SUM(L33:L36) -> 5.5645161 | M37: =SUM(M33:M36) -> 4.213125 | N37: =SUM(N33:N36) -> 5.7459677 | O37: =SUM(O33:O36) -> 5.6903226 | ... S37: =SUM(S33:S36) -> 2.141129 | V37: Rows 31 to 65 calculate the monthly impact of each Rain Exposure factor
A39: Rainfall | B39: Direct | C39: Consequential | D39: Total
A40: <1mm | B40: ='Rain+Other Factors'!G8 -> 0 | C40: ='Rain+Other Factors'!H8 -> 0 | D40: =SUM(B40:C40) -> 0 | F40: =SUM(H40:S40) -> 0 | H40: =+Climate!B35*$D40*HoursPerDayRatio*H$3 -> 0 | I40: =+Climate!C35*$D40*HoursPerDayRatio*I$3 -> 0 | J40: =+Climate!D35*$D40*HoursPerDayRatio*J$3 -> 0 | K40: =+Climate!E35*$D40*HoursPerDayRatio*K$3 -> 0 | L40: =+Climate!F35*$D40*HoursPerDayRatio*L$3 -> 0 | M40: =+Climate!G35*$D40*HoursPerDayRatio*M$3 -> 0 | N40: =+Climate!H35*$D40*HoursPerDayRatio*N$3 -> 0 | O40: =+Climate!I35*$D40*HoursPerDayRatio*O$3 -> 0 | ... S40: =+Climate!M35*$D40*HoursPerDayRatio*S$3 -> 0
A41: ≥ 1 mm & < 10 mm | B41: ='Rain+Other Factors'!G9 -> 0.5 | C41: ='Rain+Other Factors'!H9 -> 0 | D41: =SUM(B41:C41) -> 0.5 | F41: =SUM(H41:S41) -> 11.26593 | H41: =+Climate!B37*$D41*HoursPerDayRatio*H$3 -> 0.36290323 | I41: =+Climate!C37*$D41*HoursPerDayRatio*I$3 -> 0.45669643 | J41: =+Climate!D37*$D41*HoursPerDayRatio*J$3 -> 0.61209677 | K41: =+Climate!E37*$D41*HoursPerDayRatio*K$3 -> 0.748125 | L41: =+Climate!F37*$D41*HoursPerDayRatio*L$3 -> 1.3306452 | M41: =+Climate!G37*$D41*HoursPerDayRatio*M$3 -> 1.089375 | N41: =+Climate!H37*$D41*HoursPerDayRatio*N$3 -> 1.5120968 | O41: =+Climate!I37*$D41*HoursPerDayRatio*O$3 -> 1.5096774 | ... S41: =+Climate!M37*$D41*HoursPerDayRatio*S$3 -> 0.38467742
A42: ≥ 10 mm & < 25 mm | B42: ='Rain+Other Factors'!G10 -> 1 | C42: ='Rain+Other Factors'!H10 -> 0.3 | D42: =SUM(B42:C42) -> 1.3 | F42: =SUM(H42:S42) -> 5.9212079 | H42: =+Climate!B39*$D42*HoursPerDayRatio*H$3 -> 0.25947581 | I42: =+Climate!C39*$D42*HoursPerDayRatio*I$3 -> 0.34473214 | J42: =+Climate!D39*$D42*HoursPerDayRatio*J$3 -> 0.43403226 | K42: =+Climate!E39*$D42*HoursPerDayRatio*K$3 -> 0.401375 | L42: =+Climate!F39*$D42*HoursPerDayRatio*L$3 -> 0.70766129 | M42: =+Climate!G39*$D42*HoursPerDayRatio*M$3 -> 0.47775 | N42: =+Climate!H39*$D42*HoursPerDayRatio*N$3 -> 0.47177419 | O42: =+Climate!I39*$D42*HoursPerDayRatio*O$3 -> 0.60387097 | ... S42: =+Climate!M39*$D42*HoursPerDayRatio*S$3 -> 0.26419355
A43: ≥ 25 mm | B43: ='Rain+Other Factors'!G11 -> 1 | C43: ='Rain+Other Factors'!H11 -> 0.5 | D43: =SUM(B43:C43) -> 1.5 | F43: =SUM(H43:S43) -> 3.4073502 | H43: =+Climate!B40*$D43*H$3 -> 0.21774194 | I43: =+Climate!C40*$D43*I$3 -> 0.58928571 | J43: =+Climate!D40*$D43*J$3 -> 0.22258065 | K43: =+Climate!E40*$D43*K$3 -> 0.475 | L43: =+Climate!F40*$D43*L$3 -> 0.24193548 | M43: =+Climate!G40*$D43*M$3 -> 0.105 | N43: =+Climate!H40*$D43*N$3 -> 0.24193548 | O43: =+Climate!I40*$D43*O$3 -> 0.11612903 | ... S43: =+Climate!M40*$D43*S$3 -> 0.29032258
A44: RAIN EXPOSURE 2 : Foundations . | F44: =SUM(H44:S44) -> 20.594488 | H44: =SUM(H40:H43) -> 0.84012097 | I44: =SUM(I40:I43) -> 1.3907143 | J44: =SUM(J40:J43) -> 1.2687097 | K44: =SUM(K40:K43) -> 1.6245 | L44: =SUM(L40:L43) -> 2.2802419 | M44: =SUM(M40:M43) -> 1.672125 | N44: =SUM(N40:N43) -> 2.2258065 | O44: =SUM(O40:O43) -> 2.2296774 | ... S44: =SUM(S40:S43) -> 0.93919355 | V44: These numbers are factored for both WorkHours/Day and WorkDays/Month
A46: Rainfall | B46: Direct | C46: Consequential | D46: Total
A47: <1mm | B47: ='Rain+Other Factors'!K8 -> 0 | C47: ='Rain+Other Factors'!L8 -> 0 | D47: =SUM(B47:C47) -> 0 | F47: =SUM(H47:S47) -> 0 | H47: =+Climate!B35*$D47*HoursPerDayRatio*H$3 -> 0 | I47: =+Climate!C35*$D47*HoursPerDayRatio*I$3 -> 0 | J47: =+Climate!D35*$D47*HoursPerDayRatio*J$3 -> 0 | K47: =+Climate!E35*$D47*HoursPerDayRatio*K$3 -> 0 | L47: =+Climate!F35*$D47*HoursPerDayRatio*L$3 -> 0 | M47: =+Climate!G35*$D47*HoursPerDayRatio*M$3 -> 0 | N47: =+Climate!H35*$D47*HoursPerDayRatio*N$3 -> 0 | O47: =+Climate!I35*$D47*HoursPerDayRatio*O$3 -> 0 | ... S47: =+Climate!M35*$D47*HoursPerDayRatio*S$3 -> 0
A48: ≥ 1 mm & < 10 mm | B48: ='Rain+Other Factors'!K9 -> 0.5 | C48: ='Rain+Other Factors'!L9 -> 0 | D48: =SUM(B48:C48) -> 0.5 | F48: =SUM(H48:S48) -> 11.26593 | H48: =+Climate!B37*$D48*HoursPerDayRatio*H$3 -> 0.36290323 | I48: =+Climate!C37*$D48*HoursPerDayRatio*I$3 -> 0.45669643 | J48: =+Climate!D37*$D48*HoursPerDayRatio*J$3 -> 0.61209677 | K48: =+Climate!E37*$D48*HoursPerDayRatio*K$3 -> 0.748125 | L48: =+Climate!F37*$D48*HoursPerDayRatio*L$3 -> 1.3306452 | M48: =+Climate!G37*$D48*HoursPerDayRatio*M$3 -> 1.089375 | N48: =+Climate!H37*$D48*HoursPerDayRatio*N$3 -> 1.5120968 | O48: =+Climate!I37*$D48*HoursPerDayRatio*O$3 -> 1.5096774 | ... S48: =+Climate!M37*$D48*HoursPerDayRatio*S$3 -> 0.38467742
...

Sheet Critical Site Works Summary
A2: PROJECT TITLE | DB2: For Projects >32 month duration click the + sign above and adjust Print settings to view the relevant number of columns. You may also have to move the JH logo, and drag the blue arrow out to the project finish
A3: OVERALL NET TENDER PROGRAMME: DELAY ANALYSIS
A4: Printed : | B4: =TODAY() -> 46312 | D4: OVERALL NET PROGRAMME - 6d Working Week, Inclusive of Fixed RDO's, Public Holidays & Xmas / Easter Shut Downs
A5: Planner : | B5: Henry Gannt | D5: ONSITE MONTH NUMBER | H5: 0 | I5: =+H5+1 -> 1 | J5: =+I5+1 -> 2 | K5: =+J5+1 -> 3 | L5: =+K5+1 -> 4 | M5: =+L5+1 -> 5 | N5: =+M5+1 -> 6 | O5: =+N5+1 -> 7 | P5: =+O5+1 -> 8 | ... CZ5: =+CY5+1 -> 96
A7: =CONCATENATE("Commence Works on Site - ",TEXT(D11,"dd-mmm-yy")) -> Commence Works on Site - 03-Sep-18 | D7: =CONCATENATE(A29," = ",C29) -> Working Days = 905 | F7: =MAX(E12:E28) -> 44641
A8: Activity (with Critical Path in RED) | C8: W.D | D8: Net Start | E8: Net Finish | CZ8: .
F9: Gross %age Weather Impact | G9: Net %age Weather Impact | H9: =I9-15 -> 43343 | I9: =IF(AND(DAY(D11)>=1,DAY(D11)<31),DATE(YEAR(D11),MONTH(D11),15),DATE(YEAR(D11),MONTH(D11)+1,15)) -> 43358 | J9: =DATE(YEAR(I9),MONTH(I9)+1,15) -> 43388 | K9: =DATE(YEAR(J9),MONTH(J9)+1,15) -> 43419 | L9: =DATE(YEAR(K9),MONTH(K9)+1,15) -> 43449 | M9: =DATE(YEAR(L9),MONTH(L9)+1,15) -> 43480 | N9: =DATE(YEAR(M9),MONTH(M9)+1,15) -> 43511 | O9: =DATE(YEAR(N9),MONTH(N9)+1,15) -> 43539 | P9: =DATE(YEAR(O9),MONTH(O9)+1,15) -> 43570 | Q9: =DATE(YEAR(P9),MONTH(P9)+1,15) -> 43600 | ... CZ9: =DATE(YEAR(CY9),MONTH(CY9)+1,15) -> 46249 | DB9: HoursPerDay:Ratio | DD9: WorkDaysperYear
A10: Assumed Date of CONTRACT AWARD | D10: 43245 | DB10: Work Hours : | DC10: =HoursPerDayRatio -> 0.375 | DD10: WorkDays | DE10: ='Project Site Calendar'!U38 -> 0.69863014
A11: Assumed START ON SITE DATE | D11: 43346 | E11: Rain Exposure Rating > | I11: 3 | J11: 3 | K11: 1 | L11: 1 | M11: 1 | N11: 1 | O11: 1 | P11: 1 | Q11: 1 | R11: 2 | S11: 2 | T11: 2 | U11: 3 | V11: 3 | W11: 3 | X11: 3 | Y11: 3 | Z11: 3 | AA11: 3 | AB11: 3 | AC11: 3 | AD11: 3 | AE11: 4 | AF11: 4 | AG11: 4 | AH11: 4 | AI11: 4 | AJ11: 4 | AK11: 4 | AL11: 4 | AM11: 4 | AN11: 4 | AO11: 4 | AP11: 4 | AQ11: 4 | AR11: 4 | AS11: 4 | DB11: Total Hours | DD11: TotalDays
A12: Site Establishment | C12: =(E12-D12+1)*DaysPerYearRatio -> 41.219178 | D12: =+D11 -> 43346 | E12: =+D12+52+6 -> 43404 | F12: =SUM(I12:CZ12)/C12 -> 0.13336663 | G12: =SUM(I12:CZ12)/(C12-SUM(I12:CZ12)) -> 0.15389048 | I12: =IF(OR(AND(I$9>=$D12,I$9<=$E12),I$9=$D12+1-DAY($D12)),I$51,"") -> 2.1845208 | J12: =IF(OR(AND(J$9>=$D12,J$9<=$E12),J$9=$D12+1-DAY($D12)),J$51,"") -> 3.3127419 | K12: =IF(OR(AND(K$9>=$D12,K$9<=$E12),K$9=$D12+1-DAY($D12)),K$51,"") | L12: =IF(OR(AND(L$9>=$D12,L$9<=$E12),L$9=$D12+1-DAY($D12)),L$51,"") | M12: =IF(OR(AND(M$9>=$D12,M$9<=$E12),M$9=$D12+1-DAY($D12)),M$51,"") | N12: =IF(OR(AND(N$9>=$D12,N$9<=$E12),N$9=$D12+1-DAY($D12)),N$51,"") | O12: =IF(OR(AND(O$9>=$D12,O$9<=$E12),O$9=$D12+1-DAY($D12)),O$51,"") | P12: =IF(OR(AND(P$9>=$D12,P$9<=$E12),P$9=$D12+1-DAY($D12)),P$51,"") | ... CZ12: =IF(OR(AND(CZ$9>=$D12,CZ$9<=$E12),CZ$9=$D12+1-DAY($D12)),CZ$51,"") | DB12: These ratios are used to multiply the Climate
D13: x | E13: x
A14: Clear & Grub + Bulk Excavation | C14: =(E14-D14+1)*DaysPerYearRatio -> 139.72603 | D14: =+E12+1 -> 43405 | E14: =+D14+180+19 -> 43604 | F14: =SUM(I14:CZ14)/C14 -> 0.19087002 | G14: =SUM(I14:CZ14)/(C14-SUM(I14:CZ14)) -> 0.23589537 | I14: =IF(OR(AND(I$9>=$D14,I$9<=$E14),I$9=$D14+1-DAY($D14)),I$51,"") | J14: =IF(OR(AND(J$9>=$D14,J$9<=$E14),J$9=$D14+1-DAY($D14)),J$51,"") | K14: =IF(OR(AND(K$9>=$D14,K$9<=$E14),K$9=$D14+1-DAY($D14)),K$51,"") -> 4.5175 | L14: =IF(OR(AND(L$9>=$D14,L$9<=$E14),L$9=$D14+1-DAY($D14)),L$51,"") -> 3.3037097 | M14: =IF(OR(AND(M$9>=$D14,M$9<=$E14),M$9=$D14+1-DAY($D14)),M$51,"") -> 2.8104839 | N14: =IF(OR(AND(N$9>=$D14,N$9<=$E14),N$9=$D14+1-DAY($D14)),N$51,"") -> 3.4404464 | O14: =IF(OR(AND(O$9>=$D14,O$9<=$E14),O$9=$D14+1-DAY($D14)),O$51,"") -> 3.0827419 | P14: =IF(OR(AND(P$9>=$D14,P$9<=$E14),P$9=$D14+1-DAY($D14)),P$51,"") -> 3.8372083 | ... CZ14: =IF(OR(AND(CZ$9>=$D14,CZ$9<=$E14),CZ$9=$D14+1-DAY($D14)),CZ$51,"") | DB14: data to calculate potential delays
D15: x | E15: x
A16: Substructure | C16: =(E16-D16+1)*DaysPerYearRatio -> 63.575342 | D16: =+E14+1 -> 43605 | E16: =+D16+90 -> 43695 | F16: =SUM(I16:CZ16)/C16 -> 0.13035074 | G16: =SUM(I16:CZ16)/(C16-SUM(I16:CZ16)) -> 0.14988886 | I16: =IF(OR(AND(I$9>=$D16,I$9<=$E16),I$9=$D16+1-DAY($D16)),I$51,"") | J16: =IF(OR(AND(J$9>=$D16,J$9<=$E16),J$9=$D16+1-DAY($D16)),J$51,"") | K16: =IF(OR(AND(K$9>=$D16,K$9<=$E16),K$9=$D16+1-DAY($D16)),K$51,"") | L16: =IF(OR(AND(L$9>=$D16,L$9<=$E16),L$9=$D16+1-DAY($D16)),L$51,"") | M16: =IF(OR(AND(M$9>=$D16,M$9<=$E16),M$9=$D16+1-DAY($D16)),M$51,"") | N16: =IF(OR(AND(N$9>=$D16,N$9<=$E16),N$9=$D16+1-DAY($D16)),N$51,"") | O16: =IF(OR(AND(O$9>=$D16,O$9<=$E16),O$9=$D16+1-DAY($D16)),O$51,"") | P16: =IF(OR(AND(P$9>=$D16,P$9<=$E16),P$9=$D16+1-DAY($D16)),P$51,"") | ... CZ16: =IF(OR(AND(CZ$9>=$D16,CZ$9<=$E16),CZ$9=$D16+1-DAY($D16)),CZ$51,"")
D17: x
A18: Precast & Steelwork Structure | C18: =(E18-D18+1)*DaysPerYearRatio -> 225.65753 | D18: =+E16+1 -> 43696 | E18: =+D18+300+21+1 -> 44018 | F18: =SUM(I18:CZ18)/C18 -> 0.093963782 | G18: =SUM(I18:CZ18)/(C18-SUM(I18:CZ18)) -> 0.10370864 | I18: =IF(OR(AND(I$9>=$D18,I$9<=$E18),I$9=$D18+1-DAY($D18)),I$51,"") | J18: =IF(OR(AND(J$9>=$D18,J$9<=$E18),J$9=$D18+1-DAY($D18)),J$51,"") | K18: =IF(OR(AND(K$9>=$D18,K$9<=$E18),K$9=$D18+1-DAY($D18)),K$51,"") | L18: =IF(OR(AND(L$9>=$D18,L$9<=$E18),L$9=$D18+1-DAY($D18)),L$51,"") | M18: =IF(OR(AND(M$9>=$D18,M$9<=$E18),M$9=$D18+1-DAY($D18)),M$51,"") | N18: =IF(OR(AND(N$9>=$D18,N$9<=$E18),N$9=$D18+1-DAY($D18)),N$51,"") | O18: =IF(OR(AND(O$9>=$D18,O$9<=$E18),O$9=$D18+1-DAY($D18)),O$51,"") | P18: =IF(OR(AND(P$9>=$D18,P$9<=$E18),P$9=$D18+1-DAY($D18)),P$51,"") | ... CZ18: =IF(OR(AND(CZ$9>=$D18,CZ$9<=$E18),CZ$9=$D18+1-DAY($D18)),CZ$51,"")
D19: x | E19: x
A20: Fitout & Finishes | C20: =(E20-D20+1)*DaysPerYearRatio -> 319.27397 | D20: =+E18+1 -> 44019 | E20: =+D20+(15*30)-11+17 -> 44475 | F20: =SUM(I20:CZ20)/C20 -> 0.038263616 | G20: =SUM(I20:CZ20)/(C20-SUM(I20:CZ20)) -> 0.039785972 | I20: =IF(OR(AND(I$9>=$D20,I$9<=$E20),I$9=$D20+1-DAY($D20)),I$51,"") | J20: =IF(OR(AND(J$9>=$D20,J$9<=$E20),J$9=$D20+1-DAY($D20)),J$51,"") | K20: =IF(OR(AND(K$9>=$D20,K$9<=$E20),K$9=$D20+1-DAY($D20)),K$51,"") | L20: =IF(OR(AND(L$9>=$D20,L$9<=$E20),L$9=$D20+1-DAY($D20)),L$51,"") | M20: =IF(OR(AND(M$9>=$D20,M$9<=$E20),M$9=$D20+1-DAY($D20)),M$51,"") | N20: =IF(OR(AND(N$9>=$D20,N$9<=$E20),N$9=$D20+1-DAY($D20)),N$51,"") | O20: =IF(OR(AND(O$9>=$D20,O$9<=$E20),O$9=$D20+1-DAY($D20)),O$51,"") | P20: =IF(OR(AND(P$9>=$D20,P$9<=$E20),P$9=$D20+1-DAY($D20)),P$51,"") | ... CZ20: =IF(OR(AND(CZ$9>=$D20,CZ$9<=$E20),CZ$9=$D20+1-DAY($D20)),CZ$51,"")
D21: x | E21: x
A22: Testing & Commissioning | C22: =(E22-D22+1)*DaysPerYearRatio -> 115.9726 | D22: =+E20+1 -> 44476 | E22: =+D22+180+3-18 -> 44641 | F22: =SUM(I22:CZ22)/C22 -> 0.035710405 | G22: =SUM(I22:CZ22)/(C22-SUM(I22:CZ22)) -> 0.037032863 | I22: =IF(OR(AND(I$9>=$D22,I$9<=$E22),I$9=$D22+1-DAY($D22)),I$51,"") | J22: =IF(OR(AND(J$9>=$D22,J$9<=$E22),J$9=$D22+1-DAY($D22)),J$51,"") | K22: =IF(OR(AND(K$9>=$D22,K$9<=$E22),K$9=$D22+1-DAY($D22)),K$51,"") | L22: =IF(OR(AND(L$9>=$D22,L$9<=$E22),L$9=$D22+1-DAY($D22)),L$51,"") | M22: =IF(OR(AND(M$9>=$D22,M$9<=$E22),M$9=$D22+1-DAY($D22)),M$51,"") | N22: =IF(OR(AND(N$9>=$D22,N$9<=$E22),N$9=$D22+1-DAY($D22)),N$51,"") | O22: =IF(OR(AND(O$9>=$D22,O$9<=$E22),O$9=$D22+1-DAY($D22)),O$51,"") | P22: =IF(OR(AND(P$9>=$D22,P$9<=$E22),P$9=$D22+1-DAY($D22)),P$51,"") | ... CZ22: =IF(OR(AND(CZ$9>=$D22,CZ$9<=$E22),CZ$9=$D22+1-DAY($D22)),CZ$51,"")
D23: x | E23: x
I24: =IF(OR(AND(I$9>=$D24,I$9<=$E24),I$9=$D24+1-DAY($D24)),I$51,"") | J24: =IF(OR(AND(J$9>=$D24,J$9<=$E24),J$9=$D24+1-DAY($D24)),J$51,"") | K24: =IF(OR(AND(K$9>=$D24,K$9<=$E24),K$9=$D24+1-DAY($D24)),K$51,"") | L24: =IF(OR(AND(L$9>=$D24,L$9<=$E24),L$9=$D24+1-DAY($D24)),L$51,"") | M24: =IF(OR(AND(M$9>=$D24,M$9<=$E24),M$9=$D24+1-DAY($D24)),M$51,"") | N24: =IF(OR(AND(N$9>=$D24,N$9<=$E24),N$9=$D24+1-DAY($D24)),N$51,"") | O24: =IF(OR(AND(O$9>=$D24,O$9<=$E24),O$9=$D24+1-DAY($D24)),O$51,"") | P24: =IF(OR(AND(P$9>=$D24,P$9<=$E24),P$9=$D24+1-DAY($D24)),P$51,"") | ... CZ24: =IF(OR(AND(CZ$9>=$D24,CZ$9<=$E24),CZ$9=$D24+1-DAY($D24)),CZ$51,"")
D25: x | E25: x
I26: =IF(OR(AND(I$9>=$D26,I$9<=$E26),I$9=$D26+1-DAY($D26)),I$51,"") | J26: =IF(OR(AND(J$9>=$D26,J$9<=$E26),J$9=$D26+1-DAY($D26)),J$51,"") | K26: =IF(OR(AND(K$9>=$D26,K$9<=$E26),K$9=$D26+1-DAY($D26)),K$51,"") | L26: =IF(OR(AND(L$9>=$D26,L$9<=$E26),L$9=$D26+1-DAY($D26)),L$51,"") | M26: =IF(OR(AND(M$9>=$D26,M$9<=$E26),M$9=$D26+1-DAY($D26)),M$51,"") | N26: =IF(OR(AND(N$9>=$D26,N$9<=$E26),N$9=$D26+1-DAY($D26)),N$51,"") | O26: =IF(OR(AND(O$9>=$D26,O$9<=$E26),O$9=$D26+1-DAY($D26)),O$51,"") | P26: =IF(OR(AND(P$9>=$D26,P$9<=$E26),P$9=$D26+1-DAY($D26)),P$51,"") | ... CZ26: =IF(OR(AND(CZ$9>=$D26,CZ$9<=$E26),CZ$9=$D26+1-DAY($D26)),CZ$51,"")
I28: =IF(OR(AND(I$9>=$D28,I$9<=$E28),I$9=$D28+1-DAY($D28)),I$51,"") | J28: =IF(OR(AND(J$9>=$D28,J$9<=$E28),J$9=$D28+1-DAY($D28)),J$51,"") | K28: =IF(OR(AND(K$9>=$D28,K$9<=$E28),K$9=$D28+1-DAY($D28)),K$51,"") | L28: =IF(OR(AND(L$9>=$D28,L$9<=$E28),L$9=$D28+1-DAY($D28)),L$51,"") | M28: =IF(OR(AND(M$9>=$D28,M$9<=$E28),M$9=$D28+1-DAY($D28)),M$51,"") | N28: =IF(OR(AND(N$9>=$D28,N$9<=$E28),N$9=$D28+1-DAY($D28)),N$51,"") | O28: =IF(OR(AND(O$9>=$D28,O$9<=$E28),O$9=$D28+1-DAY($D28)),O$51,"") | P28: =IF(OR(AND(P$9>=$D28,P$9<=$E28),P$9=$D28+1-DAY($D28)),P$51,"") | ... CZ28: =IF(OR(AND(CZ$9>=$D28,CZ$9<=$E28),CZ$9=$D28+1-DAY($D28)),CZ$51,"")
A29: Working Days | C29: =INT(SUM(C12:C28)) -> 905 | F29: =D51/C29 -> 0.086204979 | G29: =D51/(D59-D51) -> 0.094337326
A31: Inclement Weather Risk | H31: =H$9 -> 43343 | I31: =I$9 -> 43358 | J31: =J$9 -> 43388 | K31: =K$9 -> 43419 | L31: =L$9 -> 43449 | M31: =M$9 -> 43480 | N31: =N$9 -> 43511 | O31: =O$9 -> 43539 | ... CZ31: =CZ$9 -> 46249
A32: Rain risk | H32: =HLOOKUP(MONTH(H$31),'Weather Calculation'!$H$19:$S$23,2,TRUE) -> Med | I32: =HLOOKUP(MONTH(I$31),'Weather Calculation'!$H$19:$S$23,2,TRUE) -> Med | J32: =HLOOKUP(MONTH(J$31),'Weather Calculation'!$H$19:$S$23,2,TRUE) -> Med | K32: =HLOOKUP(MONTH(K$31),'Weather Calculation'!$H$19:$S$23,2,TRUE) -> Med | L32: =HLOOKUP(MONTH(L$31),'Weather Calculation'!$H$19:$S$23,2,TRUE) -> Med | M32: =HLOOKUP(MONTH(M$31),'Weather Calculation'!$H$19:$S$23,2,TRUE) -> Low | N32: =HLOOKUP(MONTH(N$31),'Weather Calculation'!$H$19:$S$23,2,TRUE) -> Low | O32: =HLOOKUP(MONTH(O$31),'Weather Calculation'!$H$19:$S$23,2,TRUE) -> Low | ... S32: =HLOOKUP(MONTH(S$31),'Weather Calculation'!$H$19:$S$23,2,TRUE) -> Med | T32: =H32 -> Med | U32: =I32 -> Med | V32: =J32 -> Med | W32: =K32 -> Med | X32: =L32 -> Med | Y32: =M32 -> Low | Z32: =N32 -> Low | AA32: =O32 -> Low | ... CZ32: =CN32 -> Med
A33: Heat risk | H33: =HLOOKUP(MONTH(H$31),'Weather Calculation'!$H$19:$S$23,3,TRUE) -> Low | I33: =HLOOKUP(MONTH(I$31),'Weather Calculation'!$H$19:$S$23,3,TRUE) -> Low | J33: =HLOOKUP(MONTH(J$31),'Weather Calculation'!$H$19:$S$23,3,TRUE) -> Med | K33: =HLOOKUP(MONTH(K$31),'Weather Calculation'!$H$19:$S$23,3,TRUE) -> Med | L33: =HLOOKUP(MONTH(L$31),'Weather Calculation'!$H$19:$S$23,3,TRUE) -> Med | M33: =HLOOKUP(MONTH(M$31),'Weather Calculation'!$H$19:$S$23,3,TRUE) -> High | N33: =HLOOKUP(MONTH(N$31),'Weather Calculation'!$H$19:$S$23,3,TRUE) -> High | O33: =HLOOKUP(MONTH(O$31),'Weather Calculation'!$H$19:$S$23,3,TRUE) -> Med | ... S33: =HLOOKUP(MONTH(S$31),'Weather Calculation'!$H$19:$S$23,3,TRUE) -> Low | T33: =H33 -> Low | U33: =I33 -> Low | V33: =J33 -> Med | W33: =K33 -> Med | X33: =L33 -> Med | Y33: =M33 -> High | Z33: =N33 -> High | AA33: =O33 -> Med | ... CZ33: =CN33 -> Low
A34: Cold / Frost risk | H34: =HLOOKUP(MONTH(H$31),'Weather Calculation'!$H$19:$S$23,4,TRUE) -> High | I34: =HLOOKUP(MONTH(I$31),'Weather Calculation'!$H$19:$S$23,4,TRUE) -> High | J34: =HLOOKUP(MONTH(J$31),'Weather Calculation'!$H$19:$S$23,4,TRUE) -> High | K34: =HLOOKUP(MONTH(K$31),'Weather Calculation'!$H$19:$S$23,4,TRUE) -> Med | L34: =HLOOKUP(MONTH(L$31),'Weather Calculation'!$H$19:$S$23,4,TRUE) -> High | M34: =HLOOKUP(MONTH(M$31),'Weather Calculation'!$H$19:$S$23,4,TRUE) -> Low | N34: =HLOOKUP(MONTH(N$31),'Weather Calculation'!$H$19:$S$23,4,TRUE) -> Low | O34: =HLOOKUP(MONTH(O$31),'Weather Calculation'!$H$19:$S$23,4,TRUE) -> Med | ... S34: =HLOOKUP(MONTH(S$31),'Weather Calculation'!$H$19:$S$23,4,TRUE) -> High | T34: =H34 -> High | U34: =I34 -> High | V34: =J34 -> High | W34: =K34 -> Med | X34: =L34 -> High | Y34: =M34 -> Low | Z34: =N34 -> Low | AA34: =O34 -> Med | ... CZ34: =CN34 -> High
A35: Wind risk | H35: =HLOOKUP(MONTH(H$31),'Weather Calculation'!$H$19:$S$23,5,TRUE) -> Med | I35: =HLOOKUP(MONTH(I$31),'Weather Calculation'!$H$19:$S$23,5,TRUE) -> Med | J35: =HLOOKUP(MONTH(J$31),'Weather Calculation'!$H$19:$S$23,5,TRUE) -> Med | K35: =HLOOKUP(MONTH(K$31),'Weather Calculation'!$H$19:$S$23,5,TRUE) -> Med | L35: =HLOOKUP(MONTH(L$31),'Weather Calculation'!$H$19:$S$23,5,TRUE) -> Med | M35: =HLOOKUP(MONTH(M$31),'Weather Calculation'!$H$19:$S$23,5,TRUE) -> Med | N35: =HLOOKUP(MONTH(N$31),'Weather Calculation'!$H$19:$S$23,5,TRUE) -> Med | O35: =HLOOKUP(MONTH(O$31),'Weather Calculation'!$H$19:$S$23,5,TRUE) -> Med | ... S35: =HLOOKUP(MONTH(S$31),'Weather Calculation'!$H$19:$S$23,5,TRUE) -> Med | T35: =H35 -> Med | U35: =I35 -> Med | V35: =J35 -> Med | W35: =K35 -> Med | X35: =L35 -> Med | Y35: =M35 -> Med | Z35: =N35 -> Med | AA35: =O35 -> Med | ... CZ35: =CN35 -> Med
A37: Climate Notes | H37: =CONCATENATE("Weather Data from BoM Weather Station ",'BOM csv data'!A8) -> Weather Data from BoM Weather Station 086077 MOORABBIN AIRPORT
A38: Delay Risk Notes
A40: Forecast Delay Allowance in Working Days | D40: Totals | CZ40: .
H41: =H$9 -> 43343 | I41: =I$9 -> 43358 | J41: =J$9 -> 43388 | K41: =K$9 -> 43419 | L41: =L$9 -> 43449 | M41: =M$9 -> 43480 | N41: =N$9 -> 43511 | O41: =O$9 -> 43539 | ... CZ41: =CZ$9 -> 46249
A42: Wet Weather | D42: =SUM(I42:CZ42) -> 54.127297 | I42: =IF(I11>0,(HLOOKUP(MONTH(I$41),'Weather Calculation'!$H$68:$S$81,(I11+1),TRUE)),0) -> 2.0771875 | J42: =IF(J11>0,(HLOOKUP(MONTH(J$41),'Weather Calculation'!$H$68:$S$81,(J11+1),TRUE)),0) -> 2.2959677 | K42: =IF(K11>0,(HLOOKUP(MONTH(K$41),'Weather Calculation'!$H$68:$S$81,(K11+1),TRUE)),0) -> 3.9375 | L42: =IF(L11>0,(HLOOKUP(MONTH(L$41),'Weather Calculation'!$H$68:$S$81,(L11+1),TRUE)),0) -> 2.141129 | M42: =IF(M11>0,(HLOOKUP(MONTH(M$41),'Weather Calculation'!$H$68:$S$81,(M11+1),TRUE)),0) -> 1.9233871 | N42: =IF(N11>0,(HLOOKUP(MONTH(N$41),'Weather Calculation'!$H$68:$S$81,(N11+1),TRUE)),0) -> 3.0790179 | O42: =IF(O11>0,(HLOOKUP(MONTH(O$41),'Weather Calculation'!$H$68:$S$81,(O11+1),TRUE)),0) -> 2.9491935 | P42: =IF(P11>0,(HLOOKUP(MONTH(P$41),'Weather Calculation'!$H$68:$S$81,(P11+1),TRUE)),0) -> 3.811875 | ... CZ42: =IF(CZ11>0,(HLOOKUP(MONTH(CZ$41),'Weather Calculation'!$H$68:$S$81,(CZ11+1),TRUE)),0) -> 0
A43: Hot Weather (Average days over 37 degrees C.) lose | C43: ='Weather Calculation'!E5 -> 0.4 | D43: =SUM(I43:CZ43) -> 4.4986175 | I43: =IF(I$9<$F$7,(HLOOKUP(MONTH(I$41),'Weather Calculation'!$H$68:$S$81,7,TRUE)),0) -> 0 | J43: =IF(J$9<$F$7,(HLOOKUP(MONTH(J$41),'Weather Calculation'!$H$68:$S$81,7,TRUE)),0) -> 0 | K43: =IF(K$9<$F$7,(HLOOKUP(MONTH(K$41),'Weather Calculation'!$H$68:$S$81,7,TRUE)),0) -> 0.08 | L43: =IF(L$9<$F$7,(HLOOKUP(MONTH(L$41),'Weather Calculation'!$H$68:$S$81,7,TRUE)),0) -> 0.16258065 | M43: =IF(M$9<$F$7,(HLOOKUP(MONTH(M$41),'Weather Calculation'!$H$68:$S$81,7,TRUE)),0) -> 0.38709677 | N43: =IF(N$9<$F$7,(HLOOKUP(MONTH(N$41),'Weather Calculation'!$H$68:$S$81,7,TRUE)),0) -> 0.36142857 | O43: =IF(O$9<$F$7,(HLOOKUP(MONTH(O$41),'Weather Calculation'!$H$68:$S$81,7,TRUE)),0) -> 0.13354839 | P43: =IF(P$9<$F$7,(HLOOKUP(MONTH(P$41),'Weather Calculation'!$H$68:$S$81,7,TRUE)),0) -> 0 | ... CZ43: =IF(CZ$9<$F$7,(HLOOKUP(MONTH(CZ$41),'Weather Calculation'!$H$68:$S$81,7,TRUE)),0) -> 0
A44: Cold Weather (<2 degress C.) Lose | C44: ='Weather Calculation'!E6 -> 0.2 | D44: =SUM(I44:CZ44) -> 4.3895914 | I44: =IF(I$9<$F$7,(HLOOKUP(MONTH(I$41),'Weather Calculation'!$H$68:$S$81,8,TRUE)),0) -> 0.10733333 | J44: =IF(J$9<$F$7,(HLOOKUP(MONTH(J$41),'Weather Calculation'!$H$68:$S$81,8,TRUE)),0) -> 0.016774194 | K44: =IF(K$9<$F$7,(HLOOKUP(MONTH(K$41),'Weather Calculation'!$H$68:$S$81,8,TRUE)),0) -> 0 | L44: =IF(L$9<$F$7,(HLOOKUP(MONTH(L$41),'Weather Calculation'!$H$68:$S$81,8,TRUE)),0) -> 0 | M44: =IF(M$9<$F$7,(HLOOKUP(MONTH(M$41),'Weather Calculation'!$H$68:$S$81,8,TRUE)),0) -> 0 | N44: =IF(N$9<$F$7,(HLOOKUP(MONTH(N$41),'Weather Calculation'!$H$68:$S$81,8,TRUE)),0) -> 0 | O44: =IF(O$9<$F$7,(HLOOKUP(MONTH(O$41),'Weather Calculation'!$H$68:$S$81,8,TRUE)),0) -> 0 | P44: =IF(P$9<$F$7,(HLOOKUP(MONTH(P$41),'Weather Calculation'!$H$68:$S$81,8,TRUE)),0) -> 0.025333333 | ... CZ44: =IF(CZ$9<$F$7,(HLOOKUP(MONTH(CZ$41),'Weather Calculation'!$H$68:$S$81,8,TRUE)),0) -> 0
A45: Wind (Assumption) | D45: =SUM(I45:CZ45) -> 8 | I45: =IF(I$9<$F$7,(HLOOKUP(MONTH(I$41),'Weather Calculation'!$H$68:$S$81,9,TRUE)),0) -> 0 | J45: =IF(J$9<$F$7,(HLOOKUP(MONTH(J$41),'Weather Calculation'!$H$68:$S$81,9,TRUE)),0) -> 0.5 | K45: =IF(K$9<$F$7,(HLOOKUP(MONTH(K$41),'Weather Calculation'!$H$68:$S$81,9,TRUE)),0) -> 0.5 | L45: =IF(L$9<$F$7,(HLOOKUP(MONTH(L$41),'Weather Calculation'!$H$68:$S$81,9,TRUE)),0) -> 0.5 | M45: =IF(M$9<$F$7,(HLOOKUP(MONTH(M$41),'Weather Calculation'!$H$68:$S$81,9,TRUE)),0) -> 0.5 | N45: =IF(N$9<$F$7,(HLOOKUP(MONTH(N$41),'Weather Calculation'!$H$68:$S$81,9,TRUE)),0) -> 0 | O45: =IF(O$9<$F$7,(HLOOKUP(MONTH(O$41),'Weather Calculation'!$H$68:$S$81,9,TRUE)),0) -> 0 | P45: =IF(P$9<$F$7,(HLOOKUP(MONTH(P$41),'Weather Calculation'!$H$68:$S$81,9,TRUE)),0) -> 0 | ... CZ45: =IF(CZ$9<$F$7,(HLOOKUP(MONTH(CZ$41),'Weather Calculation'!$H$68:$S$81,9,TRUE)),0) -> 0
A46: Client / Authority | D46: =SUM(I46:CZ46) -> 0 | I46: =IF(I$9<$F$7,(HLOOKUP(MONTH(I$41),'Weather Calculation'!$H$68:$S$81,10,TRUE)),0) -> 0 | J46: =IF(J$9<$F$7,(HLOOKUP(MONTH(J$41),'Weather Calculation'!$H$68:$S$81,10,TRUE)),0) -> 0 | K46: =IF(K$9<$F$7,(HLOOKUP(MONTH(K$41),'Weather Calculation'!$H$68:$S$81,10,TRUE)),0) -> 0 | L46: =IF(L$9<$F$7,(HLOOKUP(MONTH(L$41),'Weather Calculation'!$H$68:$S$81,10,TRUE)),0) -> 0 | M46: =IF(M$9<$F$7,(HLOOKUP(MONTH(M$41),'Weather Calculation'!$H$68:$S$81,10,TRUE)),0) -> 0 | N46: =IF(N$9<$F$7,(HLOOKUP(MONTH(N$41),'Weather Calculation'!$H$68:$S$81,10,TRUE)),0) -> 0 | O46: =IF(O$9<$F$7,(HLOOKUP(MONTH(O$41),'Weather Calculation'!$H$68:$S$81,10,TRUE)),0) -> 0 | P46: =IF(P$9<$F$7,(HLOOKUP(MONTH(P$41),'Weather Calculation'!$H$68:$S$81,10,TRUE)),0) -> 0 | ... CZ46: =IF(CZ$9<$F$7,(HLOOKUP(MONTH(CZ$41),'Weather Calculation'!$H$68:$S$81,10,TRUE)),0) -> 0
...

Sheet Rain+Other Factors
B1: Typical Standard Rain Factors
C3: EXPOSURE 1 CIVIL Bulk Earthworks & Inground Works below -0.75m | G3: EXPOSURE 2 CIVIL Detailed Excavation BUILDING Foundations and Ground Slabs | K3: EXPOSURE 3 BUILDING Structure & Envelope | O3: EXPOSURE 4 BUILDING Fitout & Finishes (sheltered) | S3: EXPOSURE 5 CUSTOM RAIN IMPACTS Customise as necessary
B6: Daily | C6: Direct | D6: Consequential | E6: Total | G6: Direct | H6: Consequential | I6: Total | K6: Direct | L6: Consequential | M6: Total | O6: Direct | P6: Consequential | Q6: Total | S6: Direct | T6: Consequential | U6: Total
B7: Rainfall | C7: Impact | D7: Delay | E7: Impact | G7: Impact | H7: Delay | I7: Impact | K7: Impact | L7: Delay | M7: Impact | O7: Impact | P7: Delay | Q7: Impact | S7: Impact | T7: Delay | U7: Impact
B8: <1mm | C8: 0 | D8: 0 | E8: =SUM(C8:D8) -> 0 | G8: 0 | H8: 0 | I8: =SUM(G8:H8) -> 0 | K8: 0 | L8: 0 | M8: =SUM(K8:L8) -> 0 | O8: 0 | P8: 0 | Q8: =SUM(O8:P8) -> 0 | S8: 0 | T8: 0 | U8: =SUM(S8:T8) -> 0
B9: >1mm | C9: 0.5 | D9: 1 | E9: =SUM(C9:D9) -> 1.5 | G9: 0.5 | H9: 0 | I9: =SUM(G9:H9) -> 0.5 | K9: 0.5 | L9: 0 | M9: =SUM(K9:L9) -> 0.5 | O9: 0 | P9: 0 | Q9: =SUM(O9:P9) -> 0 | S9: 0 | T9: 0 | U9: =SUM(S9:T9) -> 0
B10: >10mm | C10: 1 | D10: 1 | E10: =SUM(C10:D10) -> 2 | G10: 1 | H10: 0.3 | I10: =SUM(G10:H10) -> 1.3 | K10: 1 | L10: 0.25 | M10: =SUM(K10:L10) -> 1.25 | O10: 0.5 | P10: 0 | Q10: =SUM(O10:P10) -> 0.5 | S10: 0.25 | T10: 0 | U10: =SUM(S10:T10) -> 0.25
B11: >25mm | C11: 1 | D11: 2 | E11: =SUM(C11:D11) -> 3 | G11: 1 | H11: 0.5 | I11: =SUM(G11:H11) -> 1.5 | K11: 1 | L11: 0.5 | M11: =SUM(K11:L11) -> 1.5 | O11: 0.5 | P11: 0 | Q11: =SUM(O11:P11) -> 0.5 | S11: 0.75 | T11: 0 | U11: =SUM(S11:T11) -> 0.75
B17: RAIN SUMMARY TABLE
B18: Exposure | C18: Total Impacts of Daily Rainfall
B19: Level | C19: <1mm | D19: >1mm | E19: >10mm | F19: >25mm
B20: 1 | C20: =E8 -> 0 | D20: =E9 -> 1.5 | E20: =E10 -> 2 | F20: =E11 -> 3
B21: 2 | C21: =I8 -> 0 | D21: =I9 -> 0.5 | E21: =I10 -> 1.3 | F21: =I11 -> 1.5
B22: 3 | C22: =M8 -> 0 | D22: =M9 -> 0.5 | E22: =M10 -> 1.25 | F22: =M11 -> 1.5
B23: 4 | C23: =Q8 -> 0 | D23: =Q9 -> 0 | E23: =Q10 -> 0.5 | F23: =Q11 -> 0.5
A24: Custom | B24: 5 | C24: =U8 -> 0 | D24: =U9 -> 0 | E24: =U10 -> 0.25 | F24: =U11 -> 0.75
B27: Note : The Standard Rain factors above are editable to account for specific ground conditions, or specific project issues. However the reasons for using non-standard factors MUST be discussed and agreed with Bid Leaders or Project Manager and documeted in the Basis of Schedule

Sheet Project Site Calendar
W1: INSTRUCTIONS :
B2: SETCTION A : Typical Annual Non Work Days FOR REFERENCE | I2: TYPICAL CALENDAR YEAR | W2: Rows 2 to 27 (Section A) shows Typical Non Work Days for various Australian States & Territories. These are for reference. For other regions please refer to Google and local calendars | AE2: TYPICAL WORK WEEK
H3: Source | I3: 42736 | J3: 42767 | K3: 42798 | L3: 42829 | M3: 42860 | N3: 42891 | O3: 42922 | P3: 42953 | Q3: 42984 | R3: 43015 | S3: 43046 | T3: 43077 | AE3: Day | AF3: Work Hours
B4: Calendar Days (Feb has 29 days for Leap Years) | I4: 31 | J4: 28 | K4: 31 | L4: 30 | M4: 31 | N4: 30 | O4: 31 | P4: 31 | Q4: 30 | R4: 31 | S4: 30 | T4: 31 | U4: =SUM(I4:T4) -> 365 | AE4: Sunday
B5: Typical Annual Public Holidays 7 National Hols: 2@Christmas, 2@Easter, New Year Day, Australia Day + Anzac Day 3 or 4 Annual State Public Holidays + Show Days Check Calendars or Google | G5: National | I5: 2 | L5: 3 | T5: 2 | U5: =SUM(I5:T5) -> 7 | W5: Rows 29 to 36 (Section B) Populate these cells with the relevant non-work days for the specific project under consideration. Copy and paste from Section A and /or edit as appropriate | AE5: Monday | AF5: 9
G6: ACT | J6: 1 | N6: 1 | Q6: 1 | R6: 1 | U6: =SUM(I6:T6) -> 4 | AE6: Tuesday | AF6: 9
G7: NSW | N7: 1 | P7: 1 | R7: 1 | U7: =SUM(I7:T7) -> 3 | AE7: Wednesday | AF7: 9
G8: NT | M8: 1 | N8: 1 | P8: 1 | U8: =SUM(I8:T8) -> 3 | W8: Comments (right click Insert Comment) can also be added to cells in Section B to record specific holidays that have been included | AE8: Thursday | AF8: 9
G9: QLD | M9: 1 | P9: 1 | R9: 1 | U9: =SUM(I9:T9) -> 3 | AE9: Friday | AF9: 9
G10: SA | J10: 1 | N10: 1 | R10: 1 | U10: =SUM(I10:T10) -> 3 | AE10: Saturday | AF10: 9
G11: TAS | K11: 1 | N11: 1 | R11: 1 | U11: =SUM(I11:T11) -> 3
G12: VIC | J12: 1 | N12: 1 | Q12: 1 | S12: 1 | U12: =SUM(I12:T12) -> 4 | AE12: Hours/Week | AF12: =SUM(AF4:AF11) -> 54
G13: WA | J13: 1 | N13: 1 | R13: 1 | U13: =SUM(I13:T13) -> 3
AE14: HoursPerDay:Ratio
B15: Sundays (typical 52 p.a.) | I15: 5 | J15: 4 | K15: 4 | L15: 5 | M15: 4 | N15: 4 | O15: 5 | P15: 4 | Q15: 4 | R15: 5 | S15: 4 | T15: 4 | U15: =SUM(I15:T15) -> 52 | AE15: Work Hours : | AF15: =+AF12/(COUNTIF((AF4:AF10),">0")*24) -> 0.375
B16: Non Work Saturdays - depends on site roster | I16: 5 | J16: 4 | K16: 4 | L16: 5 | M16: 4 | N16: 4 | O16: 5 | P16: 4 | Q16: 4 | R16: 5 | S16: 4 | T16: 4 | U16: =SUM(I16:T16) -> 52 | AE16: Total Hours
B17: RDO's (These are indicative only and depend on the specific type of work and the individual trade union(s) which might be involved in the project). Please Google individual State+Union RDO Calendars
G18: ACT | H18: MBA | I18: 1 | J18: 1 | K18: 1 | L18: 1 | M18: 1 | N18: 1 | O18: 1 | P18: 1 | Q18: 1 | R18: 2 | S18: 1 | T18: 1 | U18: =SUM(I18:T18) -> 13 | AE18: Adjust the Above Table for Working Hours Per Week
G19: NSW | H19: CFMEU | I19: 1 | J19: 1 | K19: 1 | L19: 1 | M19: 1 | N19: 1 | O19: 1 | P19: 1 | Q19: 1 | R19: 1 | S19: 1 | T19: 2 | U19: =SUM(I19:T19) -> 13
G20: NT | H20: CFMEU | I20: 2 | J20: 1 | K20: 1 | L20: 1 | M20: 1 | N20: 1 | O20: 1 | P20: 1 | Q20: 1 | R20: 1 | S20: 1 | T20: 1 | U20: =SUM(I20:T20) -> 13 | AE20: This Ratio is used in the calculations in the Green TAB
G21: QLD | H21: CFMEU | I21: 2 | J21: 1 | K21: 1 | L21: 1 | M21: 1 | N21: 1 | O21: 1 | P21: 1 | Q21: 1 | R21: 1 | S21: 1 | T21: 1 | U21: =SUM(I21:T21) -> 13
G22: SA | H22: MBA | I22: 1 | J22: 1 | K22: 1 | L22: 2 | M22: 1 | N22: 1 | O22: 1 | P22: 1 | Q22: 1 | R22: 1 | S22: 1 | T22: 1 | U22: =SUM(I22:T22) -> 13
G23: TAS | H23: CFMEU | I23: 2 | J23: 1 | K23: 1 | L23: 1 | M23: 1 | N23: 1 | O23: 1 | P23: 1 | Q23: 1 | R23: 1 | S23: 1 | T23: 1 | U23: =SUM(I23:T23) -> 13
G24: VIC | H24: AWU | I24: 1 | J24: 1 | K24: 1 | L24: 2 | M24: 1 | N24: 1 | O24: 1 | P24: 1 | Q24: 1 | R24: 1 | S24: 1 | T24: 1 | U24: =SUM(I24:T24) -> 13
G25: WA | H25: MBA | I25: 1 | J25: 1 | K25: 1 | L25: 1 | M25: 1 | N25: 1 | O25: 2 | P25: 1 | Q25: 1 | R25: 1 | S25: 1 | T25: 1 | U25: =SUM(I25:T25) -> 13
B27: Non Working Days (Xmas / Easter Shut Down) | I27: 4 | J27: 0 | K27: 0 | L27: 4 | M27: 0 | N27: 0 | O27: 0 | P27: 1 | Q27: 0 | R27: 0 | S27: 0 | T27: 3 | U27: =SUM(I27:T27) -> 12
B29: SECTION B : ADJUST PROJECT WORK DAY CALENDAR HERE (copy/paste + manual input/edit)
B30: Calendar Days (Feb has 29 days for Leap Years) | I30: =I4 -> 31 | J30: =J4 -> 28 | K30: =K4 -> 31 | L30: =L4 -> 30 | M30: =M4 -> 31 | N30: =N4 -> 30 | O30: =O4 -> 31 | P30: =P4 -> 31 | ... T30: =T4 -> 31 | U30: =SUM(I30:T30) -> 365
B31: Non Work SUNDAYS | I31: =+I15 -> 5 | J31: =+J15 -> 4 | K31: =+K15 -> 4 | L31: =+L15 -> 5 | M31: =+M15 -> 4 | N31: =+N15 -> 4 | O31: =+O15 -> 5 | P31: =+P15 -> 4 | ... T31: =+T15 -> 4 | U31: =SUM(I31:T31) -> 52 | V31: =+U31/$U$30 -> 0.14246575
B32: Non Work SATURDAYS | I32: 0 | J32: 0 | K32: 0 | L32: 0 | M32: 0 | N32: 0 | O32: 0 | P32: 0 | Q32: 0 | R32: 0 | S32: 0 | T32: 0 | U32: =SUM(I32:T32) -> 0 | V32: =+U32/$U$30 -> 0
